Workbook

Sheet Limites
B2: T fundo | C2: T topo | D2: Q reb
A3: mínimo | B3: =MIN(Dados!B2:K17) -> 159.39223 | C3: =MIN(Dados!L2:U17) -> 60.002298 | D3: =MIN(Caso1!D4:D19) -> 0.5
A4: máximo | B4: =MAX(Dados!B3:K18) -> 166.45335 | C4: =MAX(Dados!L3:U18) -> 162.89102 | D4: =MAX(Caso1!D4:D19) -> 3.4

Sheet Dados
A1: Carga térmica refervedor [Gcal/h] | B1: T fundo [°C] - Caso 1 | C1: T fundo [°C] - Caso 2 | D1: T fundo [°C] - Caso 3 | E1: T fundo [°C] - Caso 4 | F1: T fundo [°C] - Caso 5 | G1: T fundo [°C] - Caso 6 | H1: T fundo [°C] - Caso 7 | I1: T fundo [°C] - Caso 8 | J1: T fundo [°C] - Caso 9 | K1: T fundo [°C] - Caso 10 | L1: T topo [°C] - Caso 1 | M1: T topo [°C] - Caso 2 | N1: T topo [°C] - Caso 3 | O1: T topo [°C] - Caso 4 | P1: T topo [°C] - Caso 5 | Q1: T topo [°C] - Caso 6 | R1: T topo [°C] - Caso 7 | S1: T topo [°C] - Caso 8 | T1: T topo [°C] - Caso 9 | U1: T topo [°C] - Caso 10 | V1: Recuperação H2S [%] - Caso 1 | W1: Recuperação H2S [%] - Caso 2 | X1: Recuperação H2S [%] - Caso 3 | Y1: Recuperação H2S [%] - Caso 4 | Z1: Recuperação H2S [%] - Caso 5 | AA1: Recuperação H2S [%] - Caso 6 | AB1: Recuperação H2S [%] - Caso 7 | AC1: Recuperação H2S [%] - Caso 8 | AD1: Recuperação H2S [%] - Caso 9 | AE1: Recuperação H2S [%] - Caso 10 | AF1: Perda NH3 [%] - Caso 1 | AG1: Perda NH3 [%] - Caso 2 | AH1: Perda NH3 [%] - Caso 3 | AI1: Perda NH3 [%] - Caso 4 | AJ1: Perda NH3 [%] - Caso 5 | AK1: Perda NH3 [%] - Caso 6 | AL1: Perda NH3 [%] - Caso 7 | AM1: Perda NH3 [%] - Caso 8 | AN1: Perda NH3 [%] - Caso 9 | AO1: Perda NH3 [%] - Caso 10
A2: 2.4 | B2: =Caso1!$E9 -> 164.03851 | C2: =Caso2!$E9 -> 160.36881 | D2: =Caso3!$E9 -> 159.39223 | E2: =Caso4!$E9 -> 164.84226 | F2: =Caso5!$E9 -> 162.25076 | G2: =Caso6!$E9 -> 162.18517 | H2: =Caso7!$E9 -> 162.16413 | I2: =Caso8!$E9 -> 162.11949 | J2: =Caso9!$E9 -> 162.07497 | K2: =Caso10!$E9 -> 162.05392 | L2: =Caso1!$F9 -> 60.336289 | M2: =Caso2!$F9 -> 60.2448 | N2: =Caso3!$F9 -> 60.201987 | O2: =Caso4!$F9 -> 60.384111 | P2: =Caso5!$F9 -> 60.002298 | Q2: =Caso6!$F9 -> 60.143031 | R2: =Caso7!$F9 -> 60.155143 | S2: =Caso8!$F9 -> 60.288958 | T2: =Caso9!$F9 -> 60.427215 | U2: =Caso10!$F9 -> 60.440209 | V2: =Caso1!$S9 -> 84.375577 | W2: =Caso2!$S9 -> 56.14079 | X2: =Caso3!$S9 -> 48.874492 | Y2: =Caso4!$S9 -> 91.010949 | Z2: =Caso5!$S9 -> 1.4495225 | AA2: =Caso6!$S9 -> 52.294438 | AB2: =Caso7!$S9 -> 56.6574 | AC2: =Caso8!$S9 -> 69.249393 | AD2: =Caso9!$S9 -> 75.556523 | AE2: =Caso10!$S9 -> 77.732173 | AF2: =Caso1!$T9 -> 0.0018563779 | AG2: =Caso2!$T9 -> 0.0011422335 | AH2: =Caso3!$T9 -> 0.00094751964 | AI2: =Caso4!$T9 -> 0.0021612077 | AJ2: =Caso5!$T9 -> 2.3721678e-05 | AK2: =Caso6!$T9 -> 0.00093371341 | AL2: =Caso7!$T9 -> 0.0005707595 | AM2: =Caso8!$T9 -> 0.0014611698 | AN2: =Caso9!$T9 -> 0.0032120692 | AO2: =Caso10!$T9 -> 0.0021231713
A3: 2.5 | B3: =Caso1!$E10 -> 165.71789 | C3: =Caso2!$E10 -> 161.90494 | D3: =Caso3!$E10 -> 161.00286 | E3: =Caso4!$E10 -> 165.91824 | F3: =Caso5!$E10 -> 163.853 | G3: =Caso6!$E10 -> 163.78847 | H3: =Caso7!$E10 -> 163.76659 | I3: =Caso8!$E10 -> 163.72397 | J3: =Caso9!$E10 -> 163.68153 | K3: =Caso10!$E10 -> 163.6596 | L3: =Caso1!$F10 -> 60.394579 | M3: =Caso2!$F10 -> 60.296879 | N3: =Caso3!$F10 -> 60.252334 | O3: =Caso4!$F10 -> 60.853878 | P3: =Caso5!$F10 -> 60.052925 | Q3: =Caso6!$F10 -> 60.195626 | R3: =Caso7!$F10 -> 60.20841 | S3: =Caso8!$F10 -> 60.343702 | T3: =Caso9!$F10 -> 60.483374 | U3: =Caso10!$F10 -> 60.497082 | V3: =Caso1!$S10 -> 98.301021 | W3: =Caso2!$S10 -> 67.694866 | X3: =Caso3!$S10 -> 60.73906 | Y3: =Caso4!$S10 -> 100 | Z3: =Caso5!$S10 -> 39.159524 | AA3: =Caso6!$S10 -> 71.207884 | AB3: =Caso7!$S10 -> 75.734356 | AC3: =Caso8!$S10 -> 81.897751 | AD3: =Caso9!$S10 -> 84.991187 | AE3: =Caso10!$S10 -> 87.248585 | AF3: =Caso1!$T10 -> 0.0022875883 | AG3: =Caso2!$T10 -> 0.0014390682 | AH3: =Caso3!$T10 -> 0.0012209234 | AI3: =Caso4!$T10 -> 0.30623612 | AJ3: =Caso5!$T10 -> 0.0006464283 | AK3: =Caso6!$T10 -> 0.0013046121 | AL3: =Caso7!$T10 -> 0.0008005358 | AM3: =Caso8!$T10 -> 0.0018159702 | AN3: =Caso9!$T10 -> 0.0037800854 | AO3: =Caso10!$T10 -> 0.0025653031
A4: 2.6 | B4: =Caso1!$E11 -> 165.92844 | C4: =Caso2!$E11 -> 163.43767 | D4: =Caso3!$E11 -> 162.60998 | E4: =Caso4!$E11 -> 165.93484 | F4: =Caso5!$E11 -> 165.45162 | G4: =Caso6!$E11 -> 165.38823 | H4: =Caso7!$E11 -> 165.36553 | I4: =Caso8!$E11 -> 165.32494 | J4: =Caso9!$E11 -> 165.28461 | K4: =Caso10!$E11 -> 165.26184 | L4: =Caso1!$F11 -> 61.294057 | M4: =Caso2!$F11 -> 60.351397 | N4: =Caso3!$F11 -> 60.305054 | O4: =Caso4!$F11 -> 61.72671 | P4: =Caso5!$F11 -> 60.10653 | Q4: =Caso6!$F11 -> 60.251422 | R4: =Caso7!$F11 -> 60.264918 | S4: =Caso8!$F11 -> 60.401673 | T4: =Caso9!$F11 -> 60.54275 | U4: =Caso10!$F11 -> 60.557177 | V4: =Caso1!$S11 -> 100 | W4: =Caso2!$S11 -> 79.671634 | X4: =Caso3!$S11 -> 73.063218 | Y4: =Caso4!$S11 -> 99.999993 | Z4: =Caso5!$S11 -> 78.288808 | AA4: =Caso6!$S11 -> 90.832338 | AB4: =Caso7!$S11 -> 95.524802 | AC4: =Caso8!$S11 -> 95.021325 | AD4: =Caso9!$S11 -> 94.782069 | AE4: =Caso10!$S11 -> 97.122441 | AF4: =Caso1!$T11 -> 1.7367285 | AG4: =Caso2!$T11 -> 0.0017806411 | AH4: =Caso3!$T11 -> 0.0015310692 | AI4: =Caso4!$T11 -> 3.1065186 | AJ4: =Caso5!$T11 -> 0.0013062755 | AK4: =Caso6!$T11 -> 0.0017158671 | AL4: =Caso7!$T11 -> 0.0010676643 | AM4: =Caso8!$T11 -> 0.0022291635 | AN4: =Caso9!$T11 -> 0.0044346273 | AO4: =Caso10!$T11 -> 0.0030945753
A5: 2.7 | B5: =Caso1!$E12 -> 165.95551 | C5: =Caso2!$E12 -> 164.9672 | D5: =Caso3!$E12 -> 164.21345 | E5: =Caso4!$E12 -> 165.96213 | F5: =Caso5!$E12 -> 166.31373 | G5: =Caso6!$E12 -> 166.11774 | H5: =Caso7!$E12 -> 165.72852 | I5: =Caso8!$E12 -> 165.92196 | J5: =Caso9!$E12 -> 166.11677 | K5: =Caso10!$E12 -> 165.72664 | L5: =Caso1!$F12 -> 62.331606 | M5: =Caso2!$F12 -> 60.409011 | N5: =Caso3!$F12 -> 60.361092 | O5: =Caso4!$F12 -> 63.081242 | P5: =Caso5!$F12 -> 60.447533 | Q5: =Caso6!$F12 -> 60.795276 | R5: =Caso7!$F12 -> 60.954986 | S5: =Caso8!$F12 -> 61.132721 | T5: =Caso9!$F12 -> 61.22596 | U5: =Caso10!$F12 -> 61.482213 | V5: =Caso1!$S12 -> 100 | W5: =Caso2!$S12 -> 92.079105 | X5: =Caso3!$S12 -> 85.856178 | Y5: =Caso4!$S12 -> 99.999994 | Z5: =Caso5!$S12 -> 100 | AA5: =Caso6!$S12 -> 100 | AB5: =Caso7!$S12 -> 100 | AC5: =Caso8!$S12 -> 100 | AD5: =Caso9!$S12 -> 100 | AE5: =Caso10!$S12 -> 99.999999 | AF5: =Caso1!$T12 -> 6.3143924 | AG5: =Caso2!$T12 -> 0.0021779324 | AH5: =Caso3!$T12 -> 0.0018866377 | AI5: =Caso4!$T12 -> 7.7074002 | AJ5: =Caso5!$T12 -> 0.55756425 | AK5: =Caso6!$T12 -> 0.72815468 | AL5: =Caso7!$T12 -> 1.2456742 | AM5: =Caso8!$T12 -> 0.93537044 | AN5: =Caso9!$T12 -> 0.65470927 | AO5: =Caso10!$T12 -> 1.1785157
A6: 2.8 | B6: =Caso1!$E13 -> 165.98951 | C6: =Caso2!$E13 -> 165.91719 | D6: =Caso3!$E13 -> 165.8134 | E6: =Caso4!$E13 -> 165.99292 | F6: =Caso5!$E13 -> 166.32052 | G6: =Caso6!$E13 -> 166.13213 | H6: =Caso7!$E13 -> 165.75971 | I6: =Caso8!$E13 -> 165.94474 | J6: =Caso9!$E13 -> 166.13139 | K6: =Caso10!$E13 -> 165.7584 | L6: =Caso1!$F13 -> 64.513586 | M6: =Caso2!$F13 -> 60.93723 | N6: =Caso3!$F13 -> 60.419837 | O6: =Caso4!$F13 -> 65.90759 | P6: =Caso5!$F13 -> 60.761179 | Q6: =Caso6!$F13 -> 61.422114 | R6: =Caso7!$F13 -> 61.983125 | S6: =Caso8!$F13 -> 62.065181 | T6: =Caso9!$F13 -> 62.233039 | U6: =Caso10!$F13 -> 62.723857 | V6: =Caso1!$S13 -> 99.999993 | W6: =Caso2!$S13 -> 100 | X6: =Caso3!$S13 -> 99.127512 | Y6: =Caso4!$S13 -> 99.999998 | Z6: =Caso5!$S13 -> 100 | AA6: =Caso6!$S13 -> 99.99999 | AB6: =Caso7!$S13 -> 99.99997 | AC6: =Caso8!$S13 -> 100 | AD6: =Caso9!$S13 -> 100 | AE6: =Caso10!$S13 -> 99.999996 | AF6: =Caso1!$T13 -> 12.063054 | AG6: =Caso2!$T13 -> 0.39715817 | AH6: =Caso3!$T13 -> 0.0022984049 | AI6: =Caso4!$T13 -> 12.899374 | AJ6: =Caso5!$T13 -> 3.9981743 | AK6: =Caso6!$T13 -> 4.3756503 | AL6: =Caso7!$T13 -> 5.1884723 | AM6: =Caso8!$T13 -> 4.7752269 | AN6: =Caso9!$T13 -> 4.3557062 | AO6: =Caso10!$T13 -> 5.1889038
A7: 2.9 | B7: =Caso1!$E14 -> 166.02541 | C7: =Caso2!$E14 -> 165.93538 | D7: =Caso3!$E14 -> 165.92841 | E7: =Caso4!$E14 -> 166.02466 | F7: =Caso5!$E14 -> 166.33099 | G7: =Caso6!$E14 -> 166.15312 | H7: =Caso7!$E14 -> 165.80102 | I7: =Caso8!$E14 -> 165.9762 | J7: =Caso9!$E14 -> 166.15268 | K7: =Caso10!$E14 -> 165.80025 | L7: =Caso1!$F14 -> 69.130419 | M7: =Caso2!$F14 -> 61.853975 | N7: =Caso3!$F14 -> 61.400146 | O7: =Caso4!$F14 -> 71.670741 | P7: =Caso5!$F14 -> 61.524346 | Q7: =Caso6!$F14 -> 62.7001 | R7: =Caso7!$F14 -> 64.807466 | S7: =Caso8!$F14 -> 63.86153 | T7: =Caso9!$F14 -> 63.644202 | U7: =Caso10!$F14 -> 65.022802 | V7: =Caso1!$S14 -> 99.999973 | W7: =Caso2!$S14 -> 99.999999 | X7: =Caso3!$S14 -> 99.999992 | Y7: =Caso4!$S14 -> 99.999964 | Z7: =Caso5!$S14 -> 99.999984 | AA7: =Caso6!$S14 -> 99.999985 | AB7: =Caso7!$S14 -> 99.999939 | AC7: =Caso8!$S14 -> 99.999992 | AD7: =Caso9!$S14 -> 99.99999 | AE7: =Caso10!$S14 -> 100 | AF7: =Caso1!$T14 -> 18.134097 | AG7: =Caso2!$T14 -> 3.4580884 | AH7: =Caso3!$T14 -> 2.0225897 | AI7: =Caso4!$T14 -> 18.252848 | AJ7: =Caso5!$T14 -> 9.3134976 | AK7: =Caso6!$T14 -> 9.6899438 | AL7: =Caso7!$T14 -> 10.411255 | AM7: =Caso8!$T14 -> 10.078977 | AN7: =Caso9!$T14 -> 9.7397053 | AO7: =Caso10!$T14 -> 10.472718
A8: 3 | B8: =Caso1!$E15 -> 166.06162 | C8: =Caso2!$E15 -> 165.96419 | D8: =Caso3!$E15 -> 165.95744 | E8: =Caso4!$E15 -> 166.05658 | F8: =Caso5!$E15 -> 166.34262 | G8: =Caso6!$E15 -> 166.17608 | H8: =Caso7!$E15 -> 165.84542 | I8: =Caso8!$E15 -> 166.01021 | J8: =Caso9!$E15 -> 166.17586 | K8: =Caso10!$E15 -> 165.84503 | L8: =Caso1!$F15 -> 77.965849 | M8: =Caso2!$F15 -> 63.352124 | N8: =Caso3!$F15 -> 62.540273 | O8: =Caso4!$F15 -> 82.244287 | P8: =Caso5!$F15 -> 63.567474 | Q8: =Caso6!$F15 -> 65.663833 | R8: =Caso7!$F15 -> 71.088598 | S8: =Caso8!$F15 -> 67.641887 | T8: =Caso9!$F15 -> 66.166905 | U8: =Caso10!$F15 -> 69.521738 | V8: =Caso1!$S15 -> 99.999963 | W8: =Caso2!$S15 -> 99.999992 | X8: =Caso3!$S15 -> 99.999998 | Y8: =Caso4!$S15 -> 99.99999 | Z8: =Caso5!$S15 -> 99.999936 | AA8: =Caso6!$S15 -> 99.999947 | AB8: =Caso7!$S15 -> 100.01262 | AC8: =Caso8!$S15 -> 99.999979 | AD8: =Caso9!$S15 -> 99.999996 | AE8: =Caso10!$S15 -> 100 | AF8: =Caso1!$T15 -> 24.262152 | AG8: =Caso2!$T15 -> 8.3024189 | AH8: =Caso3!$T15 -> 6.9168528 | AI8: =Caso4!$T15 -> 23.640491 | AJ8: =Caso5!$T15 -> 15.213964 | AK8: =Caso6!$T15 -> 15.506585 | AL8: =Caso7!$T15 -> 16.021399 | AM8: =Caso8!$T15 -> 15.814009 | AN8: =Caso9!$T15 -> 15.602758 | AO8: =Caso10!$T15 -> 16.127503
A9: 3.1 | B9: =Caso1!$E16 -> 166.09763 | C9: =Caso2!$E16 -> 165.99638 | D9: =Caso3!$E16 -> 165.99319 | E9: =Caso4!$E16 -> 166.08845 | F9: =Caso5!$E16 -> 166.35449 | G9: =Caso6!$E16 -> 166.19947 | H9: =Caso7!$E16 -> 165.89056 | I9: =Caso8!$E16 -> 166.04479 | J9: =Caso9!$E16 -> 166.19942 | K9: =Caso10!$E16 -> 165.89049 | L9: =Caso1!$F16 -> 91.905237 | M9: =Caso2!$F16 -> 66.460253 | N9: =Caso3!$F16 -> 64.972855 | O9: =Caso4!$F16 -> 98.325248 | P9: =Caso5!$F16 -> 68.878544 | Q9: =Caso6!$F16 -> 72.210112 | R9: =Caso7!$F16 -> 82.515557 | S9: =Caso8!$F16 -> 75.093207 | T9: =Caso9!$F16 -> 70.959438 | U9: =Caso10!$F16 -> 77.669331 | V9: =Caso1!$S16 -> 99.999986 | W9: =Caso2!$S16 -> 99.999998 | X9: =Caso3!$S16 -> 99.99998 | Y9: =Caso4!$S16 -> 99.99999 | Z9: =Caso5!$S16 -> 100 | AA9: =Caso6!$S16 -> 100 | AB9: =Caso7!$S16 -> 100 | AC9: =Caso8!$S16 -> 99.999942 | AD9: =Caso9!$S16 -> 99.999999 | AE9: =Caso10!$S16 -> 99.99997 | AF9: =Caso1!$T16 -> 30.361198 | AG9: =Caso2!$T16 -> 13.713896 | AH9: =Caso3!$T16 -> 12.942993 | AI9: =Caso4!$T16 -> 29.027752 | AJ9: =Caso5!$T16 -> 21.236615 | AK9: =Caso6!$T16 -> 21.431869 | AL9: =Caso7!$T16 -> 21.737574 | AM9: =Caso8!$T16 -> 21.646747 | AN9: =Caso9!$T16 -> 21.564393 | AO9: =Caso10!$T16 -> 21.871608
A10: 3.2 | B10: =Caso1!$E17 -> 166.13329 | C10: =Caso2!$E17 -> 166.0294 | D10: =Caso3!$E17 -> 166.03065 | E10: =Caso4!$E17 -> 166.12032 | F10: =Caso5!$E17 -> 166.3663 | G10: =Caso6!$E17 -> 166.22278 | H10: =Caso7!$E17 -> 165.93569 | I10: =Caso8!$E17 -> 166.0793 | J10: =Caso9!$E17 -> 166.2229 | K10: =Caso10!$E17 -> 165.93593 | L10: =Caso1!$F17 -> 110.31672 | M10: =Caso2!$F17 -> 72.684186 | N10: =Caso3!$F17 -> 70.017122 | O10: =Caso4!$F17 -> 118.70204 | P10: =Caso5!$F17 -> 80.688192 | Q10: =Caso6!$F17 -> 84.472239 | R10: =Caso7!$F17 -> 96.77533 | S10: =Caso8!$F17 -> 87.592224 | T10: =Caso9!$F17 -> 80.11972 | U10: =Caso10!$F17 -> 90.266409 | V10: =Caso1!$S17 -> 100 | W10: =Caso2!$S17 -> 99.999963 | X10: =Caso3!$S17 -> 100 | Y10: =Caso4!$S17 -> 99.999991 | Z10: =Caso5!$S17 -> 99.999973 | AA10: =Caso6!$S17 -> 99.99998 | AB10: =Caso7!$S17 -> 99.999916 | AC10: =Caso8!$S17 -> 99.999974 | AD10: =Caso9!$S17 -> 100 | AE10: =Caso10!$S17 -> 99.99999 | AF10: =Caso1!$T17 -> 36.413398 | AG10: =Caso2!$T17 -> 19.269193 | AH10: =Caso3!$T17 -> 19.260191 | AI10: =Caso4!$T17 -> 34.438032 | AJ10: =Caso5!$T17 -> 27.233641 | AK10: =Caso6!$T17 -> 27.341503 | AL10: =Caso7!$T17 -> 27.454288 | AM10: =Caso8!$T17 -> 27.473715 | AN10: =Caso9!$T17 -> 27.507736 | AO10: =Caso10!$T17 -> 27.619814
A11: 3.3 | B11: =Caso1!$E18 -> 166.16879 | C11: =Caso2!$E18 -> 166.0625 | D11: =Caso3!$E18 -> 166.06825 | E11: =Caso4!$E18 -> 166.15259 | F11: =Caso5!$E18 -> 166.37795 | G11: =Caso6!$E18 -> 166.24584 | H11: =Caso7!$E18 -> 165.9806 | I11: =Caso8!$E18 -> 166.11356 | J11: =Caso9!$E18 -> 166.24613 | K11: =Caso10!$E18 -> 165.98118 | L11: =Caso1!$F18 -> 130.22798 | M11: =Caso2!$F18 -> 83.691552 | N11: =Caso3!$F18 -> 79.346056 | O11: =Caso4!$F18 -> 137.50654 | P11: =Caso5!$F18 -> 99.815398 | Q11: =Caso6!$F18 -> 102.68457 | R11: =Caso7!$F18 -> 113.28916 | S11: =Caso8!$F18 -> 104.96623 | T11: =Caso9!$F18 -> 96.190377 | U11: =Caso10!$F18 -> 106.81985 | V11: =Caso1!$S18 -> 100 | W11: =Caso2!$S18 -> 99.999964 | X11: =Caso3!$S18 -> 99.999942 | Y11: =Caso4!$S18 -> 100 | Z11: =Caso5!$S18 -> 99.999975 | AA11: =Caso6!$S18 -> 100 | AB11: =Caso7!$S18 -> 99.999992 | AC11: =Caso8!$S18 -> 100 | AD11: =Caso9!$S18 -> 100.00001 | AE11: =Caso10!$S18 -> 100 | AF11: =Caso1!$T18 -> 42.474538 | AG11: =Caso2!$T18 -> 24.840648 | AH11: =Caso3!$T18 -> 25.603516 | AI11: =Caso4!$T18 -> 39.965216 | AJ11: =Caso5!$T18 -> 33.148359 | AK11: =Caso6!$T18 -> 33.194801 | AL11: =Caso7!$T18 -> 33.154402 | AM11: =Caso8!$T18 -> 33.268396 | AN11: =Caso9!$T18 -> 33.398622 | AO11: =Caso10!$T18 -> 33.357462
A12: 3.4 | B12: =Caso1!$E19 -> 166.2044 | C12: =Caso2!$E19 -> 166.09543 | D12: =Caso3!$E19 -> 166.10544 | E12: =Caso4!$E19 -> 166.18523 | F12: =Caso5!$E19 -> 166.38941 | G12: =Caso6!$E19 -> 166.26869 | H12: =Caso7!$E19 -> 166.02545 | I12: =Caso8!$E19 -> 166.14769 | J12: =Caso9!$E19 -> 166.26921 | K12: =Caso10!$E19 -> 166.02643 | L12: =Caso1!$F19 -> 144.31355 | M12: =Caso2!$F19 -> 99.85289 | N12: =Caso3!$F19 -> 93.479731 | O12: =Caso4!$F19 -> 148.16742 | P12: =Caso5!$F19 -> 125.82069 | Q12: =Caso6!$F19 -> 125.43587 | R12: =Caso7!$F19 -> 130.44463 | S12: =Caso8!$F19 -> 125.1194 | T12: =Caso9!$F19 -> 118.89499 | U12: =Caso10!$F19 -> 124.84452 | V12: =Caso1!$S19 -> 99.999998 | W12: =Caso2!$S19 -> 100 | X12: =Caso3!$S19 -> 99.999987 | Y12: =Caso4!$S19 -> 100 | Z12: =Caso5!$S19 -> 99.999995 | AA12: =Caso6!$S19 -> 99.999994 | AB12: =Caso7!$S19 -> 100 | AC12: =Caso8!$S19 -> 99.999998 | AD12: =Caso9!$S19 -> 100 | AE12: =Caso10!$S19 -> 99.999999 | AF12: =Caso1!$T19 -> 48.598756 | AG12: =Caso2!$T19 -> 30.392537 | AH12: =Caso3!$T19 -> 31.884207 | AI12: =Caso4!$T19 -> 45.594334 | AJ12: =Caso5!$T19 -> 38.981403 | AK12: =Caso6!$T19 -> 39.018985 | AL12: =Caso7!$T19 -> 38.875799 | AM12: =Caso8!$T19 -> 39.070166 | AN12: =Caso9!$T19 -> 39.276619 | AO12: =Caso10!$T19 -> 39.126439
A13: 3.5 | B13: =Caso1!$E20 -> 166.23939 | C13: =Caso2!$E20 -> 166.12825 | D13: =Caso3!$E20 -> 166.14207 | E13: =Caso4!$E20 -> 166.21748 | F13: =Caso5!$E20 -> 166.40094 | G13: =Caso6!$E20 -> 166.29173 | H13: =Caso7!$E20 -> 166.0706 | I13: =Caso8!$E20 -> 166.18206 | J13: =Caso9!$E20 -> 166.29245 | K13: =Caso10!$E20 -> 166.07194 | L13: =Caso1!$F20 -> 151.35983 | M13: =Caso2!$F20 -> 119.75837 | N13: =Caso3!$F20 -> 111.63805 | O13: =Caso4!$F20 -> 153.29718 | P13: =Caso5!$F20 -> 149.73519 | Q13: =Caso6!$F20 -> 144.4815 | R13: =Caso7!$F20 -> 143.55973 | S13: =Caso8!$F20 -> 141.22281 | T13: =Caso9!$F20 -> 138.67389 | U13: =Caso10!$F20 -> 138.89308 | V13: =Caso1!$S20 -> 100 | W13: =Caso2!$S20 -> 99.999993 | X13: =Caso3!$S20 -> 99.999989 | Y13: =Caso4!$S20 -> 100 | Z13: =Caso5!$S20 -> 99.999992 | AA13: =Caso6!$S20 -> 99.999986 | AB13: =Caso7!$S20 -> 99.999998 | AC13: =Caso8!$S20 -> 99.999986 | AD13: =Caso9!$S20 -> 99.99996 | AE13: =Caso10!$S20 -> 99.999987 | AF13: =Caso1!$T20 -> 54.629888 | AG13: =Caso2!$T20 -> 35.948779 | AH13: =Caso3!$T20 -> 38.083205 | AI13: =Caso4!$T20 -> 51.155108 | AJ13: =Caso5!$T20 -> 44.914713 | AK13: =Caso6!$T20 -> 44.943055 | AL13: =Caso7!$T20 -> 44.678234 | AM13: =Caso8!$T20 -> 44.958401 | AN13: =Caso9!$T20 -> 45.250129 | AO13: =Caso10!$T20 -> 44.967003
... A38: 6 | B38: =Caso1!$E45 -> 166.50788 | C38: =Caso2!$E45 -> 166.50388 | D38: =Caso3!$E45 -> 166.50594 | E38: =Caso4!$E45 -> 166.50672 | F38: =Caso5!$E45 -> 166.50865 | G38: =Caso6!$E45 -> 166.5075 | H38: =Caso7!$E45 -> 166.50514 | I38: =Caso8!$E45 -> 166.50636 | J38: =Caso9!$E45 -> 166.50754 | K38: =Caso10!$E45 -> 166.50523 | L38: =Caso1!$F45 -> 163.73468 | M38: =Caso2!$F45 -> 163.4298 | N38: =Caso3!$F45 -> 163.47517 | O38: =Caso4!$F45 -> 163.68874 | P38: =Caso5!$F45 -> 164.6061 | Q38: =Caso6!$F45 -> 164.09475 | R38: =Caso7!$F45 -> 163.48858 | S38: =Caso8!$F45 -> 163.58909 | T38: =Caso9!$F45 -> 163.68864 | U38: =Caso10!$F45 -> 163.08899 | V38: =Caso1!$S45 -> 100 | W38: =Caso2!$S45 -> 100 | X38: =Caso3!$S45 -> 100 | Y38: =Caso4!$S45 -> 100 | Z38: =Caso5!$S45 -> 99.999937 | AA38: =Caso6!$S45 -> 100 | AB38: =Caso7!$S45 -> 100 | AC38: =Caso8!$S45 -> 100 | AD38: =Caso9!$S45 -> 100 | AE38: =Caso10!$S45 -> 100 | AF38: =Caso1!$T45 -> 99.720262 | AG38: =Caso2!$T45 -> 99.09821 | AH38: =Caso3!$T45 -> 99.416666 | AI38: =Caso4!$T45 -> 99.542579 | AJ38: =Caso5!$T45 -> 99.502313 | AK38: =Caso6!$T45 -> 99.486467 | AL38: =Caso7!$T45 -> 99.473178 | AM38: =Caso8!$T45 -> 99.483894 | AN38: =Caso9!$T45 -> 99.49778 | AO38: =Caso10!$T45 -> 99.484605

Sheet Caso1
A3: Row/Case | B3: Status | C3: Description | D3: VARY 1_x000D_ T1 _x000D_ COL-SPEC_x000D_ QN _x000D_ _x000D_ GCAL/HR _x000D_ | E3: TBOT _x000D_ _x000D_ _x000D_ _x000D_ _x000D_ C _x000D_ | F3: TTOP _x000D_ _x000D_ _x000D_ _x000D_ _x000D_ C _x000D_ | G3: H2SGAS _x000D_ _x000D_ _x000D_ _x000D_ _x000D_ KG/HR _x000D_ | H3: NH3GAS _x000D_ _x000D_ _x000D_ _x000D_ _x000D_ KG/HR _x000D_ | I3: H20GAS _x000D_ _x000D_ _x000D_ _x000D_ _x000D_ KG/HR _x000D_ | J3: H2SWATER_x000D_ _x000D_ _x000D_ _x000D_ _x000D_ KG/HR _x000D_ | K3: NH3WATER_x000D_ _x000D_ _x000D_ _x000D_ _x000D_ KG/HR _x000D_ | L3: H20WATER_x000D_ _x000D_ _x000D_ _x000D_ _x000D_ KG/HR _x000D_ | M3: H2SFEED _x000D_ _x000D_ _x000D_ _x000D_ _x000D_ KG/HR _x000D_ | N3: NH3FEED _x000D_ _x000D_ _x000D_ _x000D_ _x000D_ KG/HR _x000D_ | O3: H20FEED _x000D_ _x000D_ _x000D_ _x000D_ _x000D_ KG/HR _x000D_ | P3: FEED _x000D_ _x000D_ _x000D_ _x000D_ _x000D_ KG/HR _x000D_ | Q3: GAS _x000D_ _x000D_ _x000D_ _x000D_ _x000D_ KG/HR _x000D_ | R3: WATER _x000D_ _x000D_ _x000D_ _x000D_ _x000D_ KG/HR _x000D_ | S3: H2S RECOVER | T3: NH3 LOSS
A4: 1 | B4: Errors | D4: 0.5 | E4: 135.08901 | F4: 193.41294 | G4: 1.0037503e-06 | H4: 0.00012011723 | I4: 0.0010071211 | J4: 262.31808 | K4: 497.95592 | L4: 53600.261 | M4: 124.6875 | N4: 106.875 | O4: 47268.438 | P4: 47500 | Q4: 0.0011282421 | R4: 54360.535 | S4: =100*G4/M4 -> 8.0501276e-07 | T4: =100*H4/N4 -> 0.00011239039
A5: 2 | B5: Errors | D5: 2 | E5: 165.13945 | F5: -9.8743582 | G5: 74.636421 | H5: 0.27417479 | I5: 1.5154283 | J5: 4.8674021e-24 | K5: 246.66735 | L5: 50246.12 | M5: 124.6875 | N5: 106.875 | O5: 47268.438 | P5: 47500 | Q5: 76.426024 | R5: 50492.787 | S5: =100*G5/M5 -> 59.858784 | T5: =100*H5/N5 -> 0.25653782
A6: 3 | B6: Errors | D6: 2.1 | E6: 165.56031 | F6: -18.294103 | G6: 131.94923 | H6: 0.24356791 | I6: 2.8550427 | J6: 6.4723973e-08 | K6: 183.20255 | L6: 50250.354 | M6: 124.6875 | N6: 106.875 | O6: 47268.438 | P6: 47500 | Q6: 135.04784 | R6: 50433.557 | S6: =100*G6/M6 -> 105.82395 | T6: =100*H6/N6 -> 0.2278998
A7: 4 | B7: OK | D7: 2.2 | E7: 160.66788 | F7: 60.228165 | G7: 72.437152 | H7: 0.0012460265 | I7: 2.2275049 | J7: 52.250348 | K7: 106.88864 | L7: 50244.195 | M7: 124.6875 | N7: 106.875 | O7: 47268.438 | P7: 47500 | Q7: 74.665903 | R7: 50403.334 | S7: =100*G7/M7 -> 58.094959 | T7: =100*H7/N7 -> 0.0011658728
A8: 5 | B8: OK | D8: 2.3 | E8: 162.3552 | F8: 60.2808 | G8: 88.499537 | H8: 0.0015888401 | I8: 2.7292264 | J8: 36.187963 | K8: 106.8883 | L8: 50243.693 | M8: 124.6875 | N8: 106.875 | O8: 47268.438 | P8: 47500 | Q8: 91.230352 | R8: 50386.77 | S8: =100*G8/M8 -> 70.977072 | T8: =100*H8/N8 -> 0.001486634
A9: 6 | B9: OK | D9: 2.4 | E9: 164.03851 | F9: 60.336289 | G9: 105.2058 | H9: 0.0019840039 | I9: 3.2541054 | J9: 19.481703 | K9: 106.88791 | L9: 50243.168 | M9: 124.6875 | N9: 106.875 | O9: 47268.438 | P9: 47500 | Q9: 108.46189 | R9: 50369.538 | S9: =100*G9/M9 -> 84.375577 | T9: =100*H9/N9 -> 0.0018563779
A10: 7 | B10: OK | D10: 2.5 | E10: 165.71789 | F10: 60.394579 | G10: 122.56909 | H10: 0.00244486 | I10: 3.802916 | J10: 2.1184136 | K10: 106.88744 | L10: 50242.62 | M10: 124.6875 | N10: 106.875 | O10: 47268.438 | P10: 47500 | Q10: 126.37445 | R10: 50351.626 | S10: =100*G10/M10 -> 98.301021 | T10: =100*H10/N10 -> 0.0022875883
A11: 8 | B11: OK | D11: 2.6 | E11: 165.92844 | F11: 61.294057 | G11: 124.68751 | H11: 1.8561286 | I11: 6.9438896 | J11: 5.4183421e-20 | K11: 105.03376 | L11: 50239.479 | M11: 124.6875 | N11: 106.875 | O11: 47268.438 | P11: 47500 | Q11: 133.48752 | R11: 50344.512 | S11: =100*G11/M11 -> 100 | T11: =100*H11/N11 -> 1.7367285
A12: 9 | B12: OK | D12: 2.7 | E12: 165.95551 | F12: 62.331606 | G12: 124.6875 | H12: 6.7485068 | I12: 8.5097398 | J12: 1.1171743e-17 | K12: 100.14138 | L12: 50237.913 | M12: 124.6875 | N12: 106.875 | O12: 47268.438 | P12: 47500 | Q12: 139.94575 | R12: 50338.054 | S12: =100*G12/M12 -> 100 | T12: =100*H12/N12 -> 6.3143924
A13: 10 | B13: OK | D13: 2.8 | E13: 165.98951 | F13: 64.513586 | G13: 124.68749 | H13: 12.892389 | I13: 10.412112 | J13: 4.9441028e-18 | K13: 93.9975 | L13: 50236.01 | M13: 124.6875 | N13: 106.875 | O13: 47268.438 | P13: 47500 | Q13: 147.99199 | R13: 50330.008 | S13: =100*G13/M13 -> 99.999993 | T13: =100*H13/N13 -> 12.063054
A14: 11 | B14: OK | D14: 2.9 | E14: 166.02541 | F14: 69.130419 | G14: 124.68747 | H14: 19.380816 | I14: 13.391057 | J14: 2.3946943e-18 | K14: 87.509072 | L14: 50233.032 | M14: 124.6875 | N14: 106.875 | O14: 47268.438 | P14: 47500 | Q14: 157.45934 | R14: 50320.541 | S14: =100*G14/M14 -> 99.999973 | T14: =100*H14/N14 -> 18.134097
A15: 12 | B15: OK | D15: 3 | E15: 166.06162 | F15: 77.965849 | G15: 124.68745 | H15: 25.930175 | I15: 18.632346 | J15: 1.2411614e-18 | K15: 80.959715 | L15: 50227.79 | M15: 124.6875 | N15: 106.875 | O15: 47268.438 | P15: 47500 | Q15: 169.24998 | R15: 50308.75 | S15: =100*G15/M15 -> 99.999963 | T15: =100*H15/N15 -> 24.262152
... A45: 42 | B45: OK | D45: 6 | E45: 166.50788 | F45: 163.73468 | G45: 124.6875 | H45: 106.57603 | I45: 5147.0471 | J45: 8.9531456e-30 | K45: 0.31386036 | L45: 45099.376 | M45: 124.6875 | N45: 106.875 | O45: 47268.438 | P45: 47500 | Q45: 5378.3106 | R45: 45099.689 | S45: =100*G45/M45 -> 100 | T45: =100*H45/N45 -> 99.720262

Sheet Caso2
A3: Row/Case | B3: Status | C3: Description | D3: VARY 1_x000D_ T1 _x000D_ COL-SPEC_x000D_ QN _x000D_ _x000D_ GCAL/HR _x000D_ | E3: TBOT _x000D_ _x000D_ _x000D_ _x000D_ _x000D_ C _x000D_ | F3: TTOP _x000D_ _x000D_ _x000D_ _x000D_ _x000D_ C _x000D_ | G3: H2SGAS _x000D_ _x000D_ _x000D_ _x000D_ _x000D_ KG/HR _x000D_ | H3: NH3GAS _x000D_ _x000D_ _x000D_ _x000D_ _x000D_ KG/HR _x000D_ | I3: H20GAS _x000D_ _x000D_ _x000D_ _x000D_ _x000D_ KG/HR _x000D_ | J3: H2SWATER_x000D_ _x000D_ _x000D_ _x000D_ _x000D_ KG/HR _x000D_ | K3: NH3WATER_x000D_ _x000D_ _x000D_ _x000D_ _x000D_ KG/HR _x000D_ | L3: H20WATER_x000D_ _x000D_ _x000D_ _x000D_ _x000D_ KG/HR _x000D_ | M3: H2SFEED _x000D_ _x000D_ _x000D_ _x000D_ _x000D_ KG/HR _x000D_ | N3: NH3FEED _x000D_ _x000D_ _x000D_ _x000D_ _x000D_ KG/HR _x000D_ | O3: H20FEED _x000D_ _x000D_ _x000D_ _x000D_ _x000D_ KG/HR _x000D_ | P3: FEED _x000D_ _x000D_ _x000D_ _x000D_ _x000D_ KG/HR _x000D_ | Q3: GAS _x000D_ _x000D_ _x000D_ _x000D_ _x000D_ KG/HR _x000D_ | R3: WATER _x000D_ _x000D_ _x000D_ _x000D_ _x000D_ KG/HR _x000D_ | S3: H2S RECOVER | T3: NH3 LOSS
A4: 1 | B4: Errors | D4: 0.5 | E4: 134.68877 | F4: 225.53682 | G4: 1.0484506e-36 | H4: 0.56883072 | I4: 5.5419865e-37 | J4: 230.41328 | K4: 250.34314 | L4: 55493.57 | M4: 137.8125 | N4: 118.125 | O4: 52244.062 | P4: 52500 | Q4: 0.56883072 | R4: 55974.327 | S4: =100*G4/M4 -> 7.607805e-37 | T4: =100*H4/N4 -> 0.48154982
A5: 2 | B5: OK | D5: 2 | E5: 154.19243 | F5: 60.063997 | G5: 19.280463 | H5: 0.00029726891 | I5: 0.58743029 | J5: 118.53204 | K5: 118.13959 | L5: 55221.46 | M5: 137.8125 | N5: 118.125 | O5: 52244.062 | P5: 52500 | Q5: 19.868191 | R5: 55458.132 | S5: =100*G5/M5 -> 13.990359 | T5: =100*H5/N5 -> 0.00025165622
A6: 3 | B6: OK | D6: 2.1 | E6: 155.74165 | F6: 60.104538 | G6: 32.971002 | H6: 0.00052069474 | I6: 1.0068975 | J6: 104.8415 | K6: 118.13937 | L6: 55221.041 | M6: 137.8125 | N6: 118.125 | O6: 52244.062 | P6: 52500 | Q6: 33.97842 | R6: 55444.022 | S6: =100*G6/M6 -> 23.924537 | T6: =100*H6/N6 -> 0.00044079978
A7: 4 | B7: OK | D7: 2.2 | E7: 157.28733 | F7: 60.148629 | G7: 47.218314 | H7: 0.00076701292 | I7: 1.4455799 | J7: 90.594187 | K7: 118.13912 | L7: 55220.602 | M7: 137.8125 | N7: 118.125 | O7: 52244.062 | P7: 52500 | Q7: 48.664661 | R7: 55429.335 | S7: =100*G7/M7 -> 34.262722 | T7: =100*H7/N7 -> 0.00064932311
A8: 5 | B8: OK | D8: 2.3 | E8: 158.82951 | F8: 60.195243 | G8: 62.017224 | H8: 0.0010410928 | I8: 1.9036002 | J8: 75.795276 | K8: 118.13885 | L8: 55220.144 | M8: 137.8125 | N8: 118.125 | O8: 52244.062 | P8: 52500 | Q8: 63.921865 | R8: 55414.078 | S8: =100*G8/M8 -> 45.00116 | T8: =100*H8/N8 -> 0.00088134837
A9: 6 | B9: OK | D9: 2.4 | E9: 160.36881 | F9: 60.2448 | G9: 77.369027 | H9: 0.0013492634 | I9: 2.3812762 | J9: 60.443473 | K9: 118.13854 | L9: 55219.666 | M9: 137.8125 | N9: 118.125 | O9: 52244.062 | P9: 52500 | Q9: 79.751652 | R9: 55398.248 | S9: =100*G9/M9 -> 56.14079 | T9: =100*H9/N9 -> 0.0011422335
A10: 7 | B10: OK | D10: 2.5 | E10: 161.90494 | F10: 60.296879 | G10: 93.291987 | H10: 0.0016998993 | I10: 2.8794806 | J10: 44.520513 | K10: 118.13819 | L10: 55219.168 | M10: 137.8125 | N10: 118.125 | O10: 52244.062 | P10: 52500 | Q10: 96.173168 | R10: 55381.827 | S10: =100*G10/M10 -> 67.694866 | T10: =100*H10/N10 -> 0.0014390682
A11: 8 | B11: OK | D11: 2.6 | E11: 163.43767 | F11: 60.351397 | G11: 109.79747 | H11: 0.0021033822 | I11: 3.3988834 | J11: 28.01503 | K11: 118.13779 | L11: 55218.649 | M11: 137.8125 | N11: 118.125 | O11: 52244.062 | P11: 52500 | Q11: 113.19846 | R11: 55364.802 | S11: =100*G11/M11 -> 79.671634 | T11: =100*H11/N11 -> 0.0017806411
A12: 9 | B12: OK | D12: 2.7 | E12: 164.9672 | F12: 60.409011 | G12: 126.89652 | H12: 0.0025726827 | I12: 3.9401978 | J12: 10.915983 | K12: 118.13732 | L12: 55218.107 | M12: 137.8125 | N12: 118.125 | O12: 52244.062 | P12: 52500 | Q12: 130.83929 | R12: 55347.161 | S12: =100*G12/M12 -> 92.079105 | T12: =100*H12/N12 -> 0.0021779324
A13: 10 | B13: OK | D13: 2.8 | E13: 165.91719 | F13: 60.93723 | G13: 137.8125 | H13: 0.46914309 | I13: 6.2544198 | J13: 4.3367756e-17 | K13: 117.67075 | L13: 55215.793 | M13: 137.8125 | N13: 118.125 | O13: 52244.062 | P13: 52500 | Q13: 144.53606 | R13: 55333.464 | S13: =100*G13/M13 -> 100 | T13: =100*H13/N13 -> 0.39715817
A14: 11 | B14: OK | D14: 2.9 | E14: 165.93538 | F14: 61.853975 | G14: 137.8125 | H14: 4.0848669 | I14: 8.4663474 | J14: 2.2942023e-17 | K14: 114.05502 | L14: 55213.581 | M14: 137.8125 | N14: 118.125 | O14: 52244.062 | P14: 52500 | Q14: 150.36371 | R14: 55327.636 | S14: =100*G14/M14 -> 99.999999 | T14: =100*H14/N14 -> 3.4580884
A15: 12 | B15: OK | D15: 3 | E15: 165.96419 | F15: 63.352124 | G15: 137.81249 | H15: 9.8072323 | I15: 10.258821 | J15: 9.9262517e-18 | K15: 108.33266 | L15: 55211.789 | M15: 137.8125 | N15: 118.125 | O15: 52244.062 | P15: 52500 | Q15: 157.87854 | R15: 55320.122 | S15: =100*G15/M15 -> 99.999992 | T15: =100*H15/N15 -> 8.3024189
... A45: 42 | B45: OK | D45: 6 | E45: 166.50388 | F45: 163.4298 | G45: 137.8125 | H45: 117.05976 | I45: 4650.5544 | J45: 1.5232398e-21 | K45: 1.0801303 | L45: 50571.493 | M45: 137.8125 | N45: 118.125 | O45: 52244.062 | P45: 52500 | Q45: 4905.4266 | R45: 50572.573 | S45: =100*G45/M45 -> 100 | T45: =100*H45/N45 -> 99.09821

Sheet Caso3
A3: Row/Case | B3: Status | C3: Description | D3: VARY 1_x000D_ T1 _x000D_ COL-SPEC_x000D_ QN _x000D_ _x000D_ GCAL/HR _x000D_ | E3: TBOT _x000D_ _x000D_ _x000D_ _x000D_ _x000D_ C _x000D_ | F3: TTOP _x000D_ _x000D_ _x000D_ _x000D_ _x000D_ C _x000D_ | G3: H2SGAS _x000D_ _x000D_ _x000D_ _x000D_ _x000D_ KG/HR _x000D_ | H3: NH3GAS _x000D_ _x000D_ _x000D_ _x000D_ _x000D_ KG/HR _x000D_ | I3: H20GAS _x000D_ _x000D_ _x000D_ _x000D_ _x000D_ KG/HR _x000D_ | J3: H2SWATER_x000D_ _x000D_ _x000D_ _x000D_ _x000D_ KG/HR _x000D_ | K3: NH3WATER_x000D_ _x000D_ _x000D_ _x000D_ _x000D_ KG/HR _x000D_ | L3: H20WATER_x000D_ _x000D_ _x000D_ _x000D_ _x000D_ KG/HR _x000D_ | M3: H2SFEED _x000D_ _x000D_ _x000D_ _x000D_ _x000D_ KG/HR _x000D_ | N3: NH3FEED _x000D_ _x000D_ _x000D_ _x000D_ _x000D_ KG/HR _x000D_ | O3: H20FEED _x000D_ _x000D_ _x000D_ _x000D_ _x000D_ KG/HR _x000D_ | P3: FEED _x000D_ _x000D_ _x000D_ _x000D_ _x000D_ KG/HR _x000D_ | Q3: GAS _x000D_ _x000D_ _x000D_ _x000D_ _x000D_ KG/HR _x000D_ | R3: WATER _x000D_ _x000D_ _x000D_ _x000D_ _x000D_ KG/HR _x000D_ | S3: H2S RECOVER | T3: NH3 LOSS
A4: 1 | B4: Errors | D4: 0.5 | E4: 137.65764 | F4: 85.809547 | G4: 0.00035983551 | H4: 161.79333 | I4: 166.2616 | J4: 310.23845 | K4: 136.05585 | L4: 54340.709 | M4: 131.25 | N4: 112.5 | O4: 49756.25 | P4: 50000 | Q4: 328.05529 | R4: 54787.004 | S4: =100*G4/M4 -> 0.00027416039 | T4: =100*H4/N4 -> 143.81629
A5: 2 | B5: Errors | D5: 2 | E5: 152.91204 | F5: 60.034744 | G5: 7.6090656 | H5: 0.00011630497 | I5: 0.24528957 | J5: 123.64093 | K5: 112.51477 | L5: 52733.99 | M5: 131.25 | N5: 112.5 | O5: 49756.25 | P5: 50000 | Q5: 7.8544714 | R5: 52970.145 | S5: =100*G5/M5 -> 5.7973833 | T5: =100*H5/N5 -> 0.0001033822
A6: 3 | B6: OK | D6: 2.1 | E6: 154.53912 | F6: 60.065991 | G6: 20.926111 | H6: 0.00032074261 | I6: 0.63769619 | J6: 110.32389 | K6: 112.51457 | L6: 52733.597 | M6: 131.25 | N6: 112.5 | O6: 49756.25 | P6: 50000 | Q6: 21.564128 | R6: 52956.436 | S6: =100*G6/M6 -> 15.943704 | T6: =100*H6/N6 -> 0.00028510454
A7: 4 | B7: OK | D7: 2.2 | E7: 156.16078 | F7: 60.10977 | G7: 34.753031 | H7: 0.00054495558 | I7: 1.0616017 | J7: 96.49697 | K7: 112.51435 | L7: 52733.173 | M7: 131.25 | N7: 112.5 | O7: 49756.25 | P7: 50000 | Q7: 35.815177 | R7: 52942.185 | S7: =100*G7/M7 -> 26.478499 | T7: =100*H7/N7 -> 0.00048440496
A8: 5 | B8: OK | D8: 2.3 | E8: 157.77805 | F8: 60.154207 | G8: 49.166256 | H8: 0.00079189286 | I8: 1.5056459 | J8: 82.083744 | K8: 112.5141 | L8: 52732.73 | M8: 131.25 | N8: 112.5 | O8: 49756.25 | P8: 50000 | Q8: 50.672694 | R8: 52927.327 | S8: =100*G8/M8 -> 37.460004 | T8: =100*H8/N8 -> 0.00070390476
A9: 6 | B9: OK | D9: 2.4 | E9: 159.39223 | F9: 60.201987 | G9: 64.147771 | H9: 0.0010659596 | I9: 1.9695793 | J9: 67.102229 | K9: 112.51382 | L9: 52732.266 | M9: 131.25 | N9: 112.5 | O9: 49756.25 | P9: 50000 | Q9: 66.118417 | R9: 52911.882 | S9: =100*G9/M9 -> 48.874492 | T9: =100*H9/N9 -> 0.00094751964
A10: 7 | B10: OK | D10: 2.5 | E10: 161.00286 | F10: 60.252334 | G10: 79.720016 | H10: 0.0013735389 | I10: 2.4543819 | J10: 51.529984 | K10: 112.51352 | L10: 52731.781 | M10: 131.25 | N10: 112.5 | O10: 49756.25 | P10: 50000 | Q10: 82.175772 | R10: 52895.824 | S10: =100*G10/M10 -> 60.73906 | T10: =100*H10/N10 -> 0.0012209234
A11: 8 | B11: OK | D11: 2.6 | E11: 162.60998 | F11: 60.305054 | G11: 95.895473 | H11: 0.0017224529 | I11: 2.9607371 | J11: 35.354527 | K11: 112.51317 | L11: 52731.274 | M11: 131.25 | N11: 112.5 | O11: 49756.25 | P11: 50000 | Q11: 98.857933 | R11: 52879.142 | S11: =100*G11/M11 -> 73.063218 | T11: =100*H11/N11 -> 0.0015310692
A12: 9 | B12: OK | D12: 2.7 | E12: 164.21345 | F12: 60.361092 | G12: 112.68623 | H12: 0.0021224674 | I12: 3.4893799 | J12: 18.563765 | K12: 112.51277 | L12: 52730.746 | M12: 131.25 | N12: 112.5 | O12: 49756.25 | P12: 50000 | Q12: 116.17774 | R12: 52861.822 | S12: =100*G12/M12 -> 85.856178 | T12: =100*H12/N12 -> 0.0018866377
A13: 10 | B13: OK | D13: 2.8 | E13: 165.8134 | F13: 60.419837 | G13: 130.10486 | H13: 0.0025857055 | I13: 4.0409741 | J13: 1.1451412 | K13: 112.5123 | L13: 52730.194 | M13: 131.25 | N13: 112.5 | O13: 49756.25 | P13: 50000 | Q13: 134.14842 | R13: 52843.852 | S13: =100*G13/M13 -> 99.127512 | T13: =100*H13/N13 -> 0.0022984049
A14: 11 | B14: OK | D14: 2.9 | E14: 165.92841 | F14: 61.400146 | G14: 131.24999 | H14: 2.2754134 | I14: 7.3538975 | J14: 1.8987546e-16 | K14: 110.23948 | L14: 52726.881 | M14: 131.25 | N14: 112.5 | O14: 49756.25 | P14: 50000 | Q14: 140.8793 | R14: 52837.121 | S14: =100*G14/M14 -> 99.999992 | T14: =100*H14/N14 -> 2.0225897
A15: 12 | B15: OK | D15: 3 | E15: 165.95744 | F15: 62.540273 | G15: 131.25 | H15: 7.7814594 | I15: 9.0195469 | J15: 5.4112714e-18 | K15: 104.73343 | L15: 52725.216 | M15: 131.25 | N15: 112.5 | O15: 49756.25 | P15: 50000 | Q15: 148.05101 | R15: 52829.949 | S15: =100*G15/M15 -> 99.999998 | T15: =100*H15/N15 -> 6.9168528
... A45: 42 | B45: OK | D45: 6 | E45: 166.50594 | F45: 163.47517 | G45: 131.25 | H45: 111.84375 | I45: 4567.7322 | J45: 9.1124497e-29 | K45: 0.6711406 | L45: 48166.503 | M45: 131.25 | N45: 112.5 | O45: 49756.25 | P45: 50000 | Q45: 4810.826 | R45: 48167.174 | S45: =100*G45/M45 -> 100 | T45: =100*H45/N45 -> 99.416666

Sheet Caso4
A3: Row/Case | B3: Status | C3: Description | D3: VARY 1_x000D_ T1 _x000D_ COL-SPEC_x000D_ QN _x000D_ _x000D_ GCAL/HR _x000D_ | E3: TBOT _x000D_ _x000D_ _x000D_ _x000D_ _x000D_ C _x000D_ | F3: TTOP _x000D_ _x000D_ _x000D_ _x000D_ _x000D_ C _x000D_ | G3: H2SGAS _x000D_ _x000D_ _x000D_ _x000D_ _x000D_ KG/HR _x000D_ | H3: NH3GAS _x000D_ _x000D_ _x000D_ _x000D_ _x000D_ KG/HR _x000D_ | I3: H20GAS _x000D_ _x000D_ _x000D_ _x000D_ _x000D_ KG/HR _x000D_ | J3: H2SWATER_x000D_ _x000D_ _x000D_ _x000D_ _x000D_ KG/HR _x000D_ | K3: NH3WATER_x000D_ _x000D_ _x000D_ _x000D_ _x000D_ KG/HR _x000D_ | L3: H20WATER_x000D_ _x000D_ _x000D_ _x000D_ _x000D_ KG/HR _x000D_ | M3: H2SFEED _x000D_ _x000D_ _x000D_ _x000D_ _x000D_ KG/HR _x000D_ | N3: NH3FEED _x000D_ _x000D_ _x000D_ _x000D_ _x000D_ KG/HR _x000D_ | O3: H20FEED _x000D_ _x000D_ _x000D_ _x000D_ _x000D_ KG/HR _x000D_ | P3: FEED _x000D_ _x000D_ _x000D_ _x000D_ _x000D_ KG/HR _x000D_ | Q3: GAS _x000D_ _x000D_ _x000D_ _x000D_ _x000D_ KG/HR _x000D_ | R3: WATER _x000D_ _x000D_ _x000D_ _x000D_ _x000D_ KG/HR _x000D_ | S3: H2S RECOVER | T3: NH3 LOSS
A4: 1 | B4: Errors | D4: 0.5 | E4: 140.87011 | F4: 263.39872 | G4: 1.1788162e-14 | H4: 53.205214 | I4: 0.001885209 | J4: 216.15613 | K4: 102.80685 | L4: 54290.177 | M4: 131.25 | N4: 112.5 | O4: 49756.25 | P4: 50000 | Q4: 53.2071 | R4: 54609.14 | S4: =100*G4/M4 -> 8.9814568e-15 | T4: =100*H4/N4 -> 47.293524
A5: 2 | B5: OK | D5: 2 | E5: 158.41284 | F5: 60.170101 | G5: 54.984972 | H5: 0.00092076628 | I5: 1.6856885 | J5: 76.265028 | K5: 112.51397 | L5: 52732.549 | M5: 131.25 | N5: 112.5 | O5: 49756.25 | P5: 50000 | Q5: 56.671581 | R5: 52921.328 | S5: =100*G5/M5 -> 41.893312 | T5: =100*H5/N5 -> 0.00081845891
A6: 3 | B6: OK | D6: 2.1 | E6: 160.02555 | F6: 60.221606 | G6: 70.195729 | H6: 0.0012220476 | I6: 2.157975 | J6: 61.054271 | K6: 112.51367 | L6: 52732.077 | M6: 131.25 | N6: 112.5 | O6: 49756.25 | P6: 50000 | Q6: 72.354926 | R6: 52905.645 | S6: =100*G6/M6 -> 53.48246 | T6: =100*H6/N6 -> 0.0010862646
A7: 4 | B7: OK | D7: 2.2 | E7: 161.6348 | F7: 60.273011 | G7: 86.002767 | H7: 0.0015662718 | I7: 2.6514462 | J7: 45.247233 | K7: 112.51332 | L7: 52731.584 | M7: 131.25 | N7: 112.5 | O7: 49756.25 | P7: 50000 | Q7: 88.65578 | R7: 52889.344 | S7: =100*G7/M7 -> 65.525918 | T7: =100*H7/N7 -> 0.0013922416
A8: 5 | B8: OK | D8: 2.3 | E8: 163.2403 | F8: 60.32696 | G8: 102.41755 | H8: 0.0019646179 | I8: 3.1669101 | J8: 28.832449 | K8: 112.51292 | L8: 52731.068 | M8: 131.25 | N8: 112.5 | O8: 49756.25 | P8: 50000 | Q8: 105.58643 | R8: 52872.414 | S8: =100*G8/M8 -> 78.03242 | T8: =100*H8/N8 -> 0.001746327
A9: 6 | B9: OK | D9: 2.4 | E9: 164.84226 | F9: 60.384111 | G9: 119.45187 | H9: 0.0024313586 | I9: 3.7051592 | J9: 11.79813 | K9: 112.51246 | L9: 52730.53 | M9: 131.25 | N9: 112.5 | O9: 49756.25 | P9: 50000 | Q9: 123.15946 | R9: 52854.84 | S9: =100*G9/M9 -> 91.010949 | T9: =100*H9/N9 -> 0.0021612077
A10: 7 | B10: OK | D10: 2.5 | E10: 165.91824 | F10: 60.853878 | G10: 131.25 | H10: 0.34451564 | I10: 5.8245483 | J10: 5.1475881e-18 | K10: 112.17037 | L10: 52728.411 | M10: 131.25 | N10: 112.5 | O10: 49756.25 | P10: 50000 | Q10: 137.41906 | R10: 52840.581 | S10: =100*G10/M10 -> 100 | T10: =100*H10/N10 -> 0.30623612
A11: 8 | B11: OK | D11: 2.6 | E11: 165.93484 | F11: 61.72671 | G11: 131.24999 | H11: 3.4948334 | I11: 8.0291118 | J11: 5.4573818e-17 | K11: 109.02006 | L11: 52726.206 | M11: 131.25 | N11: 112.5 | O11: 49756.25 | P11: 50000 | Q11: 142.77394 | R11: 52835.226 | S11: =100*G11/M11 -> 99.999993 | T11: =100*H11/N11 -> 3.1065186
A12: 9 | B12: OK | D12: 2.7 | E12: 165.96213 | F12: 63.081242 | G12: 131.24999 | H12: 8.6708252 | I12: 9.688979 | J12: 2.1306139e-17 | K12: 103.84407 | L12: 52724.546 | M12: 131.25 | N12: 112.5 | O12: 49756.25 | P12: 50000 | Q12: 149.6098 | R12: 52828.39 | S12: =100*G12/M12 -> 99.999994 | T12: =100*H12/N12 -> 7.7074002
A13: 10 | B13: OK | D13: 2.8 | E13: 165.99292 | F13: 65.90759 | G13: 131.25 | H13: 14.511796 | I13: 11.988586 | J13: 9.7327972e-18 | K13: 98.003094 | L13: 52722.247 | M13: 131.25 | N13: 112.5 | O13: 49756.25 | P13: 50000 | Q13: 157.75038 | R13: 52820.25 | S13: =100*G13/M13 -> 99.999998 | T13: =100*H13/N13 -> 12.899374
A14: 11 | B14: OK | D14: 2.9 | E14: 166.02466 | F14: 71.670741 | G14: 131.24995 | H14: 20.534454 | I14: 15.712777 | J14: 4.780249e-18 | K14: 91.980441 | L14: 52718.522 | M14: 131.25 | N14: 112.5 | O14: 49756.25 | P14: 50000 | Q14: 167.49718 | R14: 52810.503 | S14: =100*G14/M14 -> 99.999964 | T14: =100*H14/N14 -> 18.252848
A15: 12 | B15: OK | D15: 3 | E15: 166.05658 | F15: 82.244287 | G15: 131.24999 | H15: 26.595553 | I15: 22.50866 | J15: 2.48234e-18 | K15: 85.919337 | L15: 52711.726 | M15: 131.25 | N15: 112.5 | O15: 49756.25 | P15: 50000 | Q15: 180.3542 | R15: 52797.646 | S15: =100*G15/M15 -> 99.99999 | T15: =100*H15/N15 -> 23.640491
... A45: 42 | B45: OK | D45: 6 | E45: 166.50672 | F45: 163.68874 | G45: 131.25 | H45: 111.9854 | I45: 5230.3633 | J45: 9.1965857e-24 | K45: 0.52948908 | L45: 47503.872 | M45: 131.25 | N45: 112.5 | O45: 49756.25 | P45: 50000 | Q45: 5473.5987 | R45: 47504.401 | S45: =100*G45/M45 -> 100 | T45: =100*H45/N45 -> 99.542579

Sheet Caso5
A3: Row/Case | B3: Status | C3: Description | D3: VARY 1_x000D_ T1 _x000D_ COL-SPEC_x000D_ QN _x000D_ _x000D_ GCAL/HR _x000D_ | E3: TBOT _x000D_ _x000D_ _x000D_ _x000D_ _x000D_ C _x000D_ | F3: TTOP _x000D_ _x000D_ _x000D_ _x000D_ _x000D_ C _x000D_ | G3: H2SGAS _x000D_ _x000D_ _x000D_ _x000D_ _x000D_ KG/HR _x000D_ | H3: NH3GAS _x000D_ _x000D_ _x000D_ _x000D_ _x000D_ KG/HR _x000D_ | I3: H20GAS _x000D_ _x000D_ _x000D_ _x000D_ _x000D_ KG/HR _x000D_ | J3: H2SWATER_x000D_ _x000D_ _x000D_ _x000D_ _x000D_ KG/HR _x000D_ | K3: NH3WATER_x000D_ _x000D_ _x000D_ _x000D_ _x000D_ KG/HR _x000D_ | L3: H20WATER_x000D_ _x000D_ _x000D_ _x000D_ _x000D_ KG/HR _x000D_ | M3: H2SFEED _x000D_ _x000D_ _x000D_ _x000D_ _x000D_ KG/HR _x000D_ | N3: NH3FEED _x000D_ _x000D_ _x000D_ _x000D_ _x000D_ KG/HR _x000D_ | O3: H20FEED _x000D_ _x000D_ _x000D_ _x000D_ _x000D_ KG/HR _x000D_ | P3: FEED _x000D_ _x000D_ _x000D_ _x000D_ _x000D_ KG/HR _x000D_ | Q3: GAS _x000D_ _x000D_ _x000D_ _x000D_ _x000D_ KG/HR _x000D_ | R3: WATER _x000D_ _x000D_ _x000D_ _x000D_ _x000D_ KG/HR _x000D_ | S3: H2S RECOVER | T3: NH3 LOSS
A4: 1 | B4: Errors | D4: 0.5 | E4: 145.08964 | F4: -136.62279 | G4: 0.47889519 | H4: 0.093526955 | I4: 0.16646484 | J4: 119.76385 | K4: 1671.2383 | L4: 55946.811 | M4: 43.75 | N4: 37.5 | O4: 49918.75 | P4: 50000 | Q4: 0.73888699 | R4: 57737.813 | S4: =100*G4/M4 -> 1.0946176 | T4: =100*H4/N4 -> 0.24940521
A5: 2 | B5: Errors | D5: 2 | E5: 160.23837 | F5: 94.705039 | G5: 693.59463 | H5: 2.0765417 | I5: 40.74139 | J5: 70.440582 | K5: 33.967456 | L5: 65925.988 | M5: 43.75 | N5: 37.5 | O5: 49918.75 | P5: 50000 | Q5: 736.41256 | R5: 66030.396 | S5: =100*G5/M5 -> 1585.3591 | T5: =100*H5/N5 -> 5.5374445
A6: 3 | B6: Errors | D6: 2.1 | E6: 157.38816 | F6: 106.06828 | G6: 3.0458399e-22 | H6: 3.9266322 | I6: 0.041121386 | J6: 89.694705 | K6: 45.485003 | L6: 53039.715 | M6: 43.75 | N6: 37.5 | O6: 49918.75 | P6: 50000 | Q6: 3.9677535 | R6: 53174.895 | S6: =100*G6/M6 -> 6.9619198e-22 | T6: =100*H6/N6 -> 10.471019
A7: 4 | B7: Errors | D7: 2.2 | E7: 159.80831 | F7: 40.280273 | G7: 3.5497808e-26 | H7: 7.1513036e-05 | I7: 5.1000607e-07 | J7: 63.304108 | K7: 159.47394 | L7: 52906.064 | M7: 43.75 | N7: 37.5 | O7: 49918.75 | P7: 50000 | Q7: 7.2023042e-05 | R7: 53128.842 | S7: =100*G7/M7 -> 8.1137847e-26 | T7: =100*H7/N7 -> 0.00019070143
A8: 5 | B8: Errors | D8: 2.3 | E8: 160.9741 | F8: -136.62279 | G8: 0.82731154 | H8: 5.0064762e-37 | I8: 0.089866499 | J8: 55.080625 | K8: 41.521988 | L8: 52898.82 | M8: 43.75 | N8: 37.5 | O8: 49918.75 | P8: 50000 | Q8: 0.91717804 | R8: 52995.423 | S8: =100*G8/M8 -> 1.8909978 | T8: =100*H8/N8 -> 1.3350603e-36
A9: 6 | B9: OK | D9: 2.4 | E9: 162.25076 | F9: 60.002298 | G9: 0.63416609 | H9: 8.8956291e-06 | I9: 0.01925817 | J9: 43.115834 | K9: 37.514881 | L9: 52896.716 | M9: 43.75 | N9: 37.5 | O9: 49918.75 | P9: 50000 | Q9: 0.65343315 | R9: 52977.347 | S9: =100*G9/M9 -> 1.4495225 | T9: =100*H9/N9 -> 2.3721678e-05
A10: 7 | B10: OK | D10: 2.5 | E10: 163.853 | F10: 60.052925 | G10: 17.132292 | H10: 0.00024241061 | I10: 0.52174274 | J10: 26.617708 | K10: 37.514648 | L10: 52896.213 | M10: 43.75 | N10: 37.5 | O10: 49918.75 | P10: 50000 | Q10: 17.654277 | R10: 52960.346 | S10: =100*G10/M10 -> 39.159524 | T10: =100*H10/N10 -> 0.0006464283
A11: 8 | B11: OK | D11: 2.6 | E11: 165.45162 | F11: 60.10653 | G11: 34.251354 | H11: 0.00048985331 | I11: 1.0462067 | J11: 9.4986464 | K11: 37.5144 | L11: 52895.689 | M11: 43.75 | N11: 37.5 | O11: 49918.75 | P11: 50000 | Q11: 35.29805 | R11: 52942.702 | S11: =100*G11/M11 -> 78.288808 | T11: =100*H11/N11 -> 0.0013062755
A12: 9 | B12: OK | D12: 2.7 | E12: 166.31373 | F12: 60.447533 | G12: 43.75 | H12: 0.20908659 | I12: 2.5031435 | J12: 4.7434876e-17 | K12: 37.305803 | L12: 52894.232 | M12: 43.75 | N12: 37.5 | O12: 49918.75 | P12: 50000 | Q12: 46.462231 | R12: 52931.538 | S12: =100*G12/M12 -> 100 | T12: =100*H12/N12 -> 0.55756425
A13: 10 | B13: OK | D13: 2.8 | E13: 166.32052 | F13: 60.761179 | G13: 43.75 | H13: 1.4993154 | I13: 3.0047087 | J13: 5.1217481e-18 | K13: 36.015575 | L13: 52893.73 | M13: 43.75 | N13: 37.5 | O13: 49918.75 | P13: 50000 | Q13: 48.254024 | R13: 52929.746 | S13: =100*G13/M13 -> 100 | T13: =100*H13/N13 -> 3.9981743
A14: 11 | B14: OK | D14: 2.9 | E14: 166.33099 | F14: 61.524346 | G14: 43.749993 | H14: 3.4925616 | I14: 3.4805756 | J14: 2.2500169e-18 | K14: 34.022329 | L14: 52893.255 | M14: 43.75 | N14: 37.5 | O14: 49918.75 | P14: 50000 | Q14: 50.72313 | R14: 52927.277 | S14: =100*G14/M14 -> 99.999984 | T14: =100*H14/N14 -> 9.3134976
A15: 12 | B15: OK | D15: 3 | E15: 166.34262 | F15: 63.567474 | G15: 43.749972 | H15: 5.7052364 | I15: 4.2275887 | J15: 1.0992232e-18 | K15: 31.809655 | L15: 52892.507 | M15: 43.75 | N15: 37.5 | O15: 49918.75 | P15: 50000 | Q15: 53.682797 | R15: 52924.317 | S15: =100*G15/M15 -> 99.999936 | T15: =100*H15/N15 -> 15.213964
... A45: 42 | B45: OK | D45: 6 | E45: 166.50865 | F45: 164.6061 | G45: 43.749972 | H45: 37.313367 | I45: 4923.6879 | J45: 9.1792904e-27 | K45: 0.20154735 | L45: 47973.047 | M45: 43.75 | N45: 37.5 | O45: 49918.75 | P45: 50000 | Q45: 5004.7513 | R45: 47973.249 | S45: =100*G45/M45 -> 99.999937 | T45: =100*H45/N45 -> 99.502313

Sheet Caso6
A3: Row/Case | B3: Status | C3: Description | D3: VARY 1_x000D_ T1 _x000D_ COL-SPEC_x000D_ QN _x000D_ _x000D_ GCAL/HR _x000D_ | E3: TBOT _x000D_ _x000D_ _x000D_ _x000D_ _x000D_ C _x000D_ | F3: TTOP _x000D_ _x000D_ _x000D_ _x000D_ _x000D_ C _x000D_ | G3: H2SGAS _x000D_ _x000D_ _x000D_ _x000D_ _x000D_ KG/HR _x000D_ | H3: NH3GAS _x000D_ _x000D_ _x000D_ _x000D_ _x000D_ KG/HR _x000D_ | I3: H20GAS _x000D_ _x000D_ _x000D_ _x000D_ _x000D_ KG/HR _x000D_ | J3: H2SWATER_x000D_ _x000D_ _x000D_ _x000D_ _x000D_ KG/HR _x000D_ | K3: NH3WATER_x000D_ _x000D_ _x000D_ _x000D_ _x000D_ KG/HR _x000D_ | L3: H20WATER_x000D_ _x000D_ _x000D_ _x000D_ _x000D_ KG/HR _x000D_ | M3: H2SFEED _x000D_ _x000D_ _x000D_ _x000D_ _x000D_ KG/HR _x000D_ | N3: NH3FEED _x000D_ _x000D_ _x000D_ _x000D_ _x000D_ KG/HR _x000D_ | O3: H20FEED _x000D_ _x000D_ _x000D_ _x000D_ _x000D_ KG/HR _x000D_ | P3: FEED _x000D_ _x000D_ _x000D_ _x000D_ _x000D_ KG/HR _x000D_ | Q3: GAS _x000D_ _x000D_ _x000D_ _x000D_ _x000D_ KG/HR _x000D_ | R3: WATER _x000D_ _x000D_ _x000D_ _x000D_ _x000D_ KG/HR _x000D_ | S3: H2S RECOVER | T3: NH3 LOSS
A4: 1 | B4: Errors | D4: 0.5 | E4: 138.63746 | F4: 65.950377 | G4: 8.0864095e-36 | H4: 0.0020775676 | I4: 0.0020766866 | J4: 129.90759 | K4: 114.78555 | L4: 52869.65 | M4: 87.5 | N4: 75 | O4: 49837.5 | P4: 50000 | Q4: 0.0041542542 | R4: 53114.344 | S4: =100*G4/M4 -> 9.2416109e-36 | T4: =100*H4/N4 -> 0.0027700901
A5: 2 | B5: Errors | D5: 2 | E5: 155.91565 | F5: -79.736557 | G5: 0.33242628 | H5: 0.13779635 | I5: 0.10595299 | J5: 99.400643 | K5: 104.60026 | L5: 52807.599 | M5: 87.5 | N5: 75 | O5: 49837.5 | P5: 50000 | Q5: 0.57617563 | R5: 53011.6 | S5: =100*G5/M5 -> 0.37991575 | T5: =100*H5/N5 -> 0.18372847
A6: 3 | B6: Errors | D6: 2.1 | E6: 165.44024 | F6: -28.320058 | G6: 51.53374 | H6: 0.00021961478 | I6: 4.8761349 | J6: 4.5869799e-07 | K6: 205.56497 | L6: 52820.336 | M6: 87.5 | N6: 75 | O6: 49837.5 | P6: 50000 | Q6: 56.410094 | R6: 53025.901 | S6: =100*G6/M6 -> 58.895703 | T6: =100*H6/N6 -> 0.00029281971
A7: 4 | B7: Errors | D7: 2.2 | E7: 166.49899 | F7: -4.8056422 | G7: 102.35234 | H7: 13.417142 | I7: 4.99189 | J7: 3.1093968e-05 | K7: 2.8165912 | L7: 71792.36 | M7: 87.5 | N7: 75 | O7: 49837.5 | P7: 50000 | Q7: 120.76138 | R7: 71795.177 | S7: =100*G7/M7 -> 116.97411 | T7: =100*H7/N7 -> 17.889523
A8: 5 | B8: OK | D8: 2.3 | E8: 160.57814 | F8: 60.084829 | G8: 29.818853 | H8: 0.00044661443 | I8: 0.90984462 | J8: 57.681143 | K8: 75.014443 | L8: 52814.575 | M8: 87.5 | N8: 75 | O8: 49837.5 | P8: 50000 | Q8: 30.729144 | R8: 52947.271 | S8: =100*G8/M8 -> 34.078689 | T8: =100*H8/N8 -> 0.00059548591
A9: 6 | B9: OK | D9: 2.4 | E9: 162.18517 | F9: 60.143031 | G9: 45.757633 | H9: 0.00070028505 | I9: 1.4004888 | J9: 41.742367 | K9: 75.01419 | L9: 52814.085 | M9: 87.5 | N9: 75 | O9: 49837.5 | P9: 50000 | Q9: 47.158822 | R9: 52930.841 | S9: =100*G9/M9 -> 52.294438 | T9: =100*H9/N9 -> 0.00093371341
A10: 7 | B10: OK | D10: 2.5 | E10: 163.78847 | F10: 60.195626 | G10: 62.306899 | H10: 0.00097845906 | I10: 1.9125676 | J10: 25.193101 | K10: 75.013912 | L10: 52813.573 | M10: 87.5 | N10: 75 | O10: 49837.5 | P10: 50000 | Q10: 64.220445 | R10: 52913.78 | S10: =100*G10/M10 -> 71.207884 | T10: =100*H10/N10 -> 0.0013046121
A11: 8 | B11: OK | D11: 2.6 | E11: 165.38823 | F11: 60.251422 | G11: 79.478295 | H11: 0.0012869004 | I11: 2.4470955 | J11: 8.0217046 | K11: 75.013603 | L11: 52813.038 | M11: 87.5 | N11: 75 | O11: 49837.5 | P11: 50000 | Q11: 81.926678 | R11: 52896.073 | S11: =100*G11/M11 -> 90.832338 | T11: =100*H11/N11 -> 0.0017158671
A12: 9 | B12: OK | D12: 2.7 | E12: 166.11774 | F12: 60.795276 | G12: 87.500001 | H12: 0.54611601 | I12: 4.6440606 | J12: 1.7004702e-16 | K12: 74.468774 | L12: 52810.841 | M12: 87.5 | N12: 75 | O12: 49837.5 | P12: 50000 | Q12: 92.690178 | R12: 52885.31 | S12: =100*G12/M12 -> 100 | T12: =100*H12/N12 -> 0.72815468
A13: 10 | B13: OK | D13: 2.8 | E13: 166.13213 | F13: 61.422114 | G13: 87.499991 | H13: 3.2817378 | I13: 5.7961052 | J13: 1.048021e-17 | K13: 71.733153 | L13: 52809.689 | M13: 87.5 | N13: 75 | O13: 49837.5 | P13: 50000 | Q13: 96.577834 | R13: 52881.422 | S13: =100*G13/M13 -> 99.99999 | T13: =100*H13/N13 -> 4.3756503
A14: 11 | B14: OK | D14: 2.9 | E14: 166.15312 | F14: 62.7001 | G14: 87.499987 | H14: 7.2674579 | I14: 6.8991371 | J14: 4.6028726e-18 | K14: 67.747433 | L14: 52808.586 | M14: 87.5 | N14: 75 | O14: 49837.5 | P14: 50000 | Q14: 101.66658 | R14: 52876.333 | S14: =100*G14/M14 -> 99.999985 | T14: =100*H14/N14 -> 9.6899438
A15: 12 | B15: OK | D15: 3 | E15: 166.17608 | F15: 65.663833 | G15: 87.499953 | H15: 11.629939 | I15: 8.5633037 | J15: 2.2267216e-18 | K15: 63.384948 | L15: 52806.922 | M15: 87.5 | N15: 75 | O15: 49837.5 | P15: 50000 | Q15: 107.6932 | R15: 52870.307 | S15: =100*G15/M15 -> 99.999947 | T15: =100*H15/N15 -> 15.506585
... A45: 42 | B45: OK | D45: 6 | E45: 166.5075 | F45: 164.09475 | G45: 87.5 | H45: 74.61485 | I45: 4911.1516 | J45: 1.1860103e-22 | K45: 0.40003959 | L45: 47904.334 | M45: 87.5 | N45: 75 | O45: 49837.5 | P45: 50000 | Q45: 5073.2665 | R45: 47904.734 | S45: =100*G45/M45 -> 100 | T45: =100*H45/N45 -> 99.486467

Sheet Caso7
A3: Row/Case | B3: Status | C3: Description | D3: VARY 1_x000D_ T1 _x000D_ COL-SPEC_x000D_ QN _x000D_ _x000D_ GCAL/HR _x000D_ | E3: TBOT _x000D_ _x000D_ _x000D_ _x000D_ _x000D_ C _x000D_ | F3: TTOP _x000D_ _x000D_ _x000D_ _x000D_ _x000D_ C _x000D_ | G3: H2SGAS _x000D_ _x000D_ _x000D_ _x000D_ _x000D_ KG/HR _x000D_ | H3: NH3GAS _x000D_ _x000D_ _x000D_ _x000D_ _x000D_ KG/HR _x000D_ | I3: H20GAS _x000D_ _x000D_ _x000D_ _x000D_ _x000D_ KG/HR _x000D_ | J3: H2SWATER_x000D_ _x000D_ _x000D_ _x000D_ _x000D_ KG/HR _x000D_ | K3: NH3WATER_x000D_ _x000D_ _x000D_ _x000D_ _x000D_ KG/HR _x000D_ | L3: H20WATER_x000D_ _x000D_ _x000D_ _x000D_ _x000D_ KG/HR _x000D_ | M3: H2SFEED _x000D_ _x000D_ _x000D_ _x000D_ _x000D_ KG/HR _x000D_ | N3: NH3FEED _x000D_ _x000D_ _x000D_ _x000D_ _x000D_ KG/HR _x000D_ | O3: H20FEED _x000D_ _x000D_ _x000D_ _x000D_ _x000D_ KG/HR _x000D_ | P3: FEED _x000D_ _x000D_ _x000D_ _x000D_ _x000D_ KG/HR _x000D_ | Q3: GAS _x000D_ _x000D_ _x000D_ _x000D_ _x000D_ KG/HR _x000D_ | R3: WATER _x000D_ _x000D_ _x000D_ _x000D_ _x000D_ KG/HR _x000D_ | S3: H2S RECOVER | T3: NH3 LOSS
A4: 1 | B4: Errors | D4: 0.5 | E4: 136.8725 | F4: 19.619669 | G4: 1.3223452 | H4: 6.6094122e-37 | I4: 6.9915735e-37 | J4: 175.73077 | K4: 1600.7132 | L4: 52761.577 | M4: 87.5 | N4: 150 | O4: 49762.5 | P4: 50000 | Q4: 1.3223452 | R4: 54538.021 | S4: =100*G4/M4 -> 1.5112517 | T4: =100*H4/N4 -> 4.4062748e-37
A5: 2 | B5: Errors | D5: 2 | E5: 155.47289 | F5: -136.72383 | G5: 0.23240346 | H5: 0.14988192 | I5: 0.24454914 | J5: 95.118241 | K5: 298.53466 | L5: 52827.55 | M5: 87.5 | N5: 150 | O5: 49762.5 | P5: 50000 | Q5: 0.62683452 | R5: 53221.203 | S5: =100*G5/M5 -> 0.26560395 | T5: =100*H5/N5 -> 0.099921277
A6: 3 | B6: Errors | D6: 2.1 | E6: 157.33493 | F6: 60.00698 | G6: 3.1234651 | H6: 4.852612e-05 | I6: 0.081791083 | J6: 84.376535 | K6: 150.01484 | L6: 52740.403 | M6: 87.5 | N6: 150 | O6: 49762.5 | P6: 50000 | Q6: 3.2053047 | R6: 52974.795 | S6: =100*G6/M6 -> 3.5696744 | T6: =100*H6/N6 -> 3.2350747e-05
A7: 4 | B7: OK | D7: 2.2 | E7: 158.94816 | F7: 60.05643 | G7: 18.014553 | H7: 0.00028838552 | I7: 0.54870269 | J7: 69.485447 | K7: 150.0146 | L7: 52739.936 | M7: 87.5 | N7: 150 | O7: 49762.5 | P7: 50000 | Q7: 18.563544 | R7: 52959.437 | S7: =100*G7/M7 -> 20.588061 | T7: =100*H7/N7 -> 0.00019225701
A8: 5 | B8: OK | D8: 2.3 | E8: 160.55789 | F8: 60.104378 | G8: 33.494938 | H8: 0.00055516593 | I8: 1.0229717 | J8: 54.005062 | K8: 150.01433 | L8: 52739.462 | M8: 87.5 | N8: 150 | O8: 49762.5 | P8: 50000 | Q8: 34.518465 | R8: 52943.482 | S8: =100*G8/M8 -> 38.279929 | T8: =100*H8/N8 -> 0.00037011062
A9: 6 | B9: OK | D9: 2.4 | E9: 162.16413 | F9: 60.155143 | G9: 49.575225 | H9: 0.00085613925 | I9: 1.5183614 | J9: 37.924775 | K9: 150.01403 | L9: 52738.967 | M9: 87.5 | N9: 150 | O9: 49762.5 | P9: 50000 | Q9: 51.094442 | R9: 52926.906 | S9: =100*G9/M9 -> 56.6574 | T9: =100*H9/N9 -> 0.0005707595
A10: 7 | B10: OK | D10: 2.5 | E10: 163.76659 | F10: 60.20841 | G10: 66.267562 | H10: 0.0012008037 | I10: 2.0355923 | J10: 21.232439 | K10: 150.01369 | L10: 52738.45 | M10: 87.5 | N10: 150 | O10: 49762.5 | P10: 50000 | Q10: 68.304355 | R10: 52909.696 | S10: =100*G10/M10 -> 75.734356 | T10: =100*H10/N10 -> 0.0008005358
A11: 8 | B11: OK | D11: 2.6 | E11: 165.36553 | F11: 60.264918 | G11: 83.584202 | H11: 0.0016014965 | I11: 2.5754413 | J11: 3.915798 | K11: 150.01329 | L11: 52737.91 | M11: 87.5 | N11: 150 | O11: 49762.5 | P11: 50000 | Q11: 86.161245 | R11: 52891.839 | S11: =100*G11/M11 -> 95.524802 | T11: =100*H11/N11 -> 0.0010676643
A12: 9 | B12: OK | D12: 2.7 | E12: 165.72852 | F12: 60.954986 | G12: 87.500001 | H12: 1.8685113 | I12: 4.9664191 | J12: 2.4829994e-15 | K12: 148.14638 | L12: 52735.519 | M12: 87.5 | N12: 150 | O12: 49762.5 | P12: 50000 | Q12: 94.334931 | R12: 52883.665 | S12: =100*G12/M12 -> 100 | T12: =100*H12/N12 -> 1.2456742
A13: 10 | B13: OK | D13: 2.8 | E13: 165.75971 | F13: 61.983125 | G13: 87.499974 | H13: 7.7827084 | I13: 6.1169855 | J13: 1.0871032e-17 | K13: 142.23218 | L13: 52734.368 | M13: 87.5 | N13: 150 | O13: 49762.5 | P13: 50000 | Q13: 101.39967 | R13: 52876.6 | S13: =100*G13/M13 -> 99.99997 | T13: =100*H13/N13 -> 5.1884723
A14: 11 | B14: OK | D14: 2.9 | E14: 165.80102 | F14: 64.807466 | G14: 87.499946 | H14: 15.616882 | I14: 7.7325739 | J14: 4.8567329e-18 | K14: 134.39802 | L14: 52732.753 | M14: 87.5 | N14: 150 | O14: 49762.5 | P14: 50000 | Q14: 110.8494 | R14: 52867.151 | S14: =100*G14/M14 -> 99.999939 | T14: =100*H14/N14 -> 10.411255
A15: 12 | B15: Errors | D15: 3 | E15: 165.84542 | F15: 71.088598 | G15: 87.511046 | H15: 24.032098 | I15: 10.475972 | J15: 4.0080133e-18 | K15: 125.97675 | L15: 52730.01 | M15: 87.5 | N15: 150 | O15: 49762.5 | P15: 50000 | Q15: 122.01912 | R15: 52855.986 | S15: =100*G15/M15 -> 100.01262 | T15: =100*H15/N15 -> 16.021399
... A45: 42 | B45: OK | D45: 6 | E45: 166.50514 | F45: 163.48858 | G45: 87.5 | H45: 149.20977 | I45: 4867.7711 | J45: 3.8813852e-25 | K45: 0.80512291 | L45: 47872.714 | M45: 87.5 | N45: 150 | O45: 49762.5 | P45: 50000 | Q45: 5104.4809 | R45: 47873.519 | S45: =100*G45/M45 -> 100 | T45: =100*H45/N45 -> 99.473178

Sheet Caso8
A3: Row/Case | B3: Status | C3: Description | D3: VARY 1_x000D_ T1 _x000D_ COL-SPEC_x000D_ QN _x000D_ _x000D_ GCAL/HR _x000D_ | E3: TBOT _x000D_ _x000D_ _x000D_ _x000D_ _x000D_ C _x000D_ | F3: TTOP _x000D_ _x000D_ _x000D_ _x000D_ _x000D_ C _x000D_ | G3: H2SGAS _x000D_ _x000D_ _x000D_ _x000D_ _x000D_ KG/HR _x000D_ | H3: NH3GAS _x000D_ _x000D_ _x000D_ _x000D_ _x000D_ KG/HR _x000D_ | I3: H20GAS _x000D_ _x000D_ _x000D_ _x000D_ _x000D_ KG/HR _x000D_ | J3: H2SWATER_x000D_ _x000D_ _x000D_ _x000D_ _x000D_ KG/HR _x000D_ | K3: NH3WATER_x000D_ _x000D_ _x000D_ _x000D_ _x000D_ KG/HR _x000D_ | L3: H20WATER_x000D_ _x000D_ _x000D_ _x000D_ _x000D_ KG/HR _x000D_ | M3: H2SFEED _x000D_ _x000D_ _x000D_ _x000D_ _x000D_ KG/HR _x000D_ | N3: NH3FEED _x000D_ _x000D_ _x000D_ _x000D_ _x000D_ KG/HR _x000D_ | O3: H20FEED _x000D_ _x000D_ _x000D_ _x000D_ _x000D_ KG/HR _x000D_ | P3: FEED _x000D_ _x000D_ _x000D_ _x000D_ _x000D_ KG/HR _x000D_ | Q3: GAS _x000D_ _x000D_ _x000D_ _x000D_ _x000D_ KG/HR _x000D_ | R3: WATER _x000D_ _x000D_ _x000D_ _x000D_ _x000D_ KG/HR _x000D_ | S3: H2S RECOVER | T3: NH3 LOSS
A4: 1 | B4: Errors | D4: 0.5 | E4: 132.35238 | F4: 84.874014 | G4: 0.00011990296 | H4: 0.00043535502 | I4: 5.3194633e-06 | J4: 235.92947 | K4: 430.40634 | L4: 52756.539 | M4: 131.25 | N4: 112.5 | O4: 49756.25 | P4: 50000 | Q4: 0.00056057744 | R4: 53422.875 | S4: =100*G4/M4 -> 9.1354634e-05 | T4: =100*H4/N4 -> 0.00038698224
A5: 2 | B5: OK | D5: 2 | E5: 155.66569 | F5: 60.09449 | G5: 30.480263 | H5: 0.00047899562 | I5: 0.93040709 | J5: 100.76974 | K5: 112.51441 | L5: 52733.305 | M5: 131.25 | N5: 112.5 | O5: 49756.25 | P5: 50000 | Q5: 31.411149 | R5: 52946.589 | S5: =100*G5/M5 -> 23.223058 | T5: =100*H5/N5 -> 0.00042577389
A6: 3 | B6: OK | D6: 2.1 | E6: 157.28473 | F6: 60.140799 | G6: 44.699493 | H6: 0.00072203878 | I6: 1.3678652 | J6: 86.550507 | K6: 112.51417 | L6: 52732.867 | M6: 131.25 | N6: 112.5 | O6: 49756.25 | P6: 50000 | Q6: 46.068081 | R6: 52931.932 | S6: =100*G6/M6 -> 34.056757 | T6: =100*H6/N6 -> 0.00064181225
A7: 4 | B7: OK | D7: 2.2 | E7: 158.89961 | F7: 60.187173 | G7: 59.510029 | H7: 0.00099275976 | I7: 1.825834 | J7: 71.739971 | K7: 112.5139 | L7: 52732.409 | M7: 131.25 | N7: 112.5 | O7: 49756.25 | P7: 50000 | Q7: 61.336856 | R7: 52916.663 | S7: =100*G7/M7 -> 45.340975 | T7: =100*H7/N7 -> 0.00088245312
A8: 5 | B8: OK | D8: 2.3 | E8: 160.5113 | F8: 60.237103 | G8: 74.900342 | H8: 0.0012972275 | I8: 2.3042991 | J8: 56.349658 | K8: 112.51359 | L8: 52731.931 | M8: 131.25 | N8: 112.5 | O8: 49756.25 | P8: 50000 | Q8: 77.205939 | R8: 52900.794 | S8: =100*G8/M8 -> 57.066928 | T8: =100*H8/N8 -> 0.0011530911
A9: 6 | B9: OK | D9: 2.4 | E9: 162.11949 | F9: 60.288958 | G9: 90.889829 | H9: 0.001643816 | I9: 2.8041403 | J9: 40.360171 | K9: 112.51325 | L9: 52731.431 | M9: 131.25 | N9: 112.5 | O9: 49756.25 | P9: 50000 | Q9: 93.695613 | R9: 52884.304 | S9: =100*G9/M9 -> 69.249393 | T9: =100*H9/N9 -> 0.0014611698
A10: 7 | B10: OK | D10: 2.5 | E10: 163.72397 | F10: 60.343702 | G10: 107.4908 | H10: 0.0020429665 | I10: 3.3261137 | J10: 23.759203 | K10: 112.51285 | L10: 52730.909 | M10: 131.25 | N10: 112.5 | O10: 49756.25 | P10: 50000 | Q10: 110.81895 | R10: 52867.181 | S10: =100*G10/M10 -> 81.897751 | T10: =100*H10/N10 -> 0.0018159702
A11: 8 | B11: OK | D11: 2.6 | E11: 165.32494 | F11: 60.401673 | G11: 124.71549 | H11: 0.0025078089 | I11: 3.8709773 | J11: 6.5345108 | K11: 112.51238 | L11: 52730.364 | M11: 131.25 | N11: 112.5 | O11: 49756.25 | P11: 50000 | Q11: 128.58897 | R11: 52849.411 | S11: =100*G11/M11 -> 95.021325 | T11: =100*H11/N11 -> 0.0022291635
A12: 9 | B12: OK | D12: 2.7 | E12: 165.92196 | F12: 61.132721 | G12: 131.25 | H12: 1.0522917 | I12: 6.7219528 | J12: 1.6921853e-15 | K12: 111.4626 | L12: 52727.513 | M12: 131.25 | N12: 112.5 | O12: 49756.25 | P12: 50000 | Q12: 139.02425 | R12: 52838.976 | S12: =100*G12/M12 -> 100 | T12: =100*H12/N12 -> 0.93537044
A13: 10 | B13: OK | D13: 2.8 | E13: 165.94474 | F13: 62.065181 | G13: 131.25 | H13: 5.3721303 | I13: 8.5042184 | J13: 1.6068036e-17 | K13: 107.14276 | L13: 52725.731 | M13: 131.25 | N13: 112.5 | O13: 49756.25 | P13: 50000 | Q13: 145.12635 | R13: 52832.874 | S13: =100*G13/M13 -> 100 | T13: =100*H13/N13 -> 4.7752269
A14: 11 | B14: OK | D14: 2.9 | E14: 165.9762 | F14: 63.86153 | G14: 131.24999 | H14: 11.338849 | I14: 10.329343 | J14: 7.0532289e-18 | K14: 101.17604 | L14: 52723.906 | M14: 131.25 | N14: 112.5 | O14: 49756.25 | P14: 50000 | Q14: 152.91818 | R14: 52825.082 | S14: =100*G14/M14 -> 99.999992 | T14: =100*H14/N14 -> 10.078977
A15: 12 | B15: OK | D15: 3 | E15: 166.01021 | F15: 67.641887 | G15: 131.24997 | H15: 17.79076 | I15: 13.056735 | J15: 3.4229648e-18 | K15: 94.724127 | L15: 52721.178 | M15: 131.25 | N15: 112.5 | O15: 49756.25 | P15: 50000 | Q15: 162.09747 | R15: 52815.902 | S15: =100*G15/M15 -> 99.999979 | T15: =100*H15/N15 -> 15.814009
... A45: 42 | B45: OK | D45: 6 | E45: 166.50636 | F45: 163.58909 | G45: 131.25 | H45: 111.91938 | I45: 4898.6109 | J45: 1.9885976e-22 | K45: 0.59550861 | L45: 47835.624 | M45: 131.25 | N45: 112.5 | O45: 49756.25 | P45: 50000 | Q45: 5141.7803 | R45: 47836.22 | S45: =100*G45/M45 -> 100 | T45: =100*H45/N45 -> 99.483894

Sheet Caso9
